<?xml version="1.0" ?>
<!-- =================================================================================== -->
<!-- |    This document was autogenerated by xacro from src/velma_robot/velma_description/robots/velma.urdf.xacro | -->
<!-- |    EDITING THIS FILE BY HAND IS NOT RECOMMENDED                                 | -->
<!-- =================================================================================== -->
<robot name="planar_manipulator" xmlns:controller="http://playerstage.sourceforge.net/gazebo/xmlschema/#controller" xmlns:geom="http://playerstage.sourceforge.net/gazebo/xmlschema/#geom" xmlns:interface="http://playerstage.sourceforge.net/gazebo/xmlschema/#interface" xmlns:sensor="http://playerstage.sourceforge.net/gazebo/xmlschema/#sensor" xmlns:xacro="http://www.ros.org/wiki/xacro">
  <!-- stereo_left_joint -->
  <!-- stereo_right_joint -->
  <!-- torso_link2_left_arm_base_joint -->
  <!-- head_base_joint -->
  <!-- head_kinect_rgb_joint -->
  <!-- left_hand_camera_joint -->
  <!-- right_gripper_calib_link1 -->
  <!-- right_gripper_calib_link2 -->
  <!-- left_gripper_calib_link1 -->
  <!-- left_gripper_calib_link2 -->
  <!-- right_gripper_calib_link -->
  <!-- left_gripper_calib_link -->
  <!-- right_gripper_calib_link1 -->
  <!-- right_gripper_calib_link2 -->
  <!-- left_gripper_calib_link1 -->
  <!-- left_gripper_calib_link2 -->
  <!--
     Little helper macro to define the inertia matrix needed
     for links.
     -->
  <!-- length is along the y-axis! -->
  <!-- right is either 1 (for right arm) or -1 (for left arm) -->
  <material name="DarkGrey">
    <color rgba="0.3 0.3 0.3 1.0"/>
  </material>
  <material name="Red">
    <color rgba="0.3 0.3 0.3 1.0"/>
  </material>
  <material name="Black">
    <color rgba="0 0 0 1.0"/>
  </material>
  <material name="Orange">
    <color rgba="1.0 0.487 0 1.0"/>
  </material>
  <material name="Silver">
    <color rgba="1.0 1.0 1.0 1.0"/>
  </material>
  <material name="Grey">
    <color rgba="0.7 0.7 0.7 1.0"/>
  </material>
  <material name="Blue">
    <color rgba="0.0 0.0 0.8 1.0"/>
  </material>
  <material name="HandGray">
    <color rgba="0.953 0.996 0.694 1.0"/>
  </material>
  <material name="SickBlue">
    <color rgba="0.3058 0.5921 0.7294 1.0"/>
  </material>
  <!--
  <include filename="$(find velma_defs)/defs/kinect_camera.urdf.xacro" />
   -->
  <link name="world"/>
  <!-- static connection between the world frame and the map frame -->
  <link name="map"/>
  <joint name="world_map_joint" type="fixed">
    <origin rpy="0 0 0" xyz="0 0 0"/>
    <parent link="world"/>
    <child link="map"/>
  </joint>
  <joint name="base_joint" type="fixed">
    <origin rpy="0 0 0" xyz="0 0 0"/>
    <parent link="world"/>
    <child link="base"/>
  </joint>
  <link name="base">
    <visual>
      <origin rpy="0.0 0 0" xyz="0 0 0"/>
      <geometry>
        <box size="1.0 0.1 0.1"/>
      </geometry>
      <material name="base">
        <color rgba="0.3 0.3 0.3 1"/>
      </material>
    </visual>
    <collision>
      <origin rpy="0.0 0 0" xyz="0 0 0"/>
      <geometry>
        <box size="1.0 0.1 0.1"/>
      </geometry>
    </collision>
    <collision2>
      <origin rpy="0 0 1.570796327" xyz="0 0 0"/>
      <geometry>
        <capsule radius="0.1" length = "1.0"/>
      </geometry>
    </collision2>
  </link>
  <joint name="0_joint" type="revolute">
    <origin rpy="0 0 0" xyz="0 0.05 0"/>
    <axis xyz="0 0 1"/>
    <limit effort="100" lower="-1.221694444" upper="1.221694444" velocity="100"/>
    <parent link="base"/>
    <child link="link1"/>
  </joint>
  <link name="link1">
    <visual>
      <origin rpy="0.0 0 0" xyz="0 0.2 0"/>
      <geometry>
        <box size="0.1 0.4 0.1"/>
      </geometry>
      <material name="link">
        <color rgba="0.5 0.5 0.5 1"/>
      </material>
    </visual>
    <collision>
      <origin rpy="0.0 0 0" xyz="0 0.2 0"/>
      <geometry>
        <box size="0.1 0.4 0.1"/>
      </geometry>
    </collision>
    <collision2>
      <origin rpy="0.0 0 0" xyz="0 0.2 0"/>
      <geometry>
        <capsule radius="0.1" length = "0.4"/>
      </geometry>
    </collision2>
  </link>
  <joint name="1_joint" type="revolute">
    <origin rpy="0 0 0" xyz="0 0.4 0"/>
    <axis xyz="0 0 1"/>
    <limit effort="100" lower="-2.792444444" upper="2.792444444" velocity="100"/>
    <parent link="link1"/>
    <child link="link2"/>
  </joint>
  <link name="link2">
    <visual>
      <origin rpy="0.0 0 0" xyz="0 0.2 0"/>
      <geometry>
        <box size="0.1 0.4 0.1"/>
      </geometry>
      <material name="link">
        <color rgba="0.5 0.5 0.5 1"/>
      </material>
    </visual>
    <collision>
      <origin rpy="0.0 0 0" xyz="0 0.2 0"/>
      <geometry>
        <box size="0.1 0.4 0.1"/>
      </geometry>
    </collision>
    <collision2>
      <origin rpy="0.0 0 0" xyz="0 0.2 0"/>
      <geometry>
        <capsule radius="0.1" length = "0.4"/>
      </geometry>
    </collision2>
  </link>
  <joint name="2_joint" type="revolute">
    <origin rpy="0 0 0" xyz="0 0.4 0"/>
    <axis xyz="0 0 1"/>
    <limit effort="100" lower="-2.792444444" upper="2.792444444" velocity="100"/>
    <parent link="link2"/>
    <child link="link3"/>
  </joint>
  <link name="link3">
    <visual>
      <origin rpy="0.0 0 0" xyz="0 0.2 0"/>
      <geometry>
        <box size="0.1 0.4 0.1"/>
      </geometry>
      <material name="link">
        <color rgba="0.5 0.5 0.5 1"/>
      </material>
    </visual>
    <collision>
      <origin rpy="0.0 0 0" xyz="0 0.2 0"/>
      <geometry>
        <box size="0.1 0.4 0.1"/>
      </geometry>
    </collision>
    <collision2>
      <origin rpy="0.0 0 0" xyz="0 0.2 0"/>
      <geometry>
        <capsule radius="0.1" length = "0.4"/>
      </geometry>
    </collision2>
  </link>
  <joint name="3_joint" type="revolute">
    <origin rpy="0 0 0" xyz="0 0.4 0"/>
    <axis xyz="0 0 1"/>
    <limit effort="100" lower="-2.792444444" upper="2.792444444" velocity="100"/>
    <parent link="link3"/>
    <child link="link4"/>
  </joint>
  <link name="link4">
    <visual>
      <origin rpy="0.0 0 0" xyz="0 0.2 0"/>
      <geometry>
        <box size="0.1 0.4 0.1"/>
      </geometry>
      <material name="link">
        <color rgba="0.5 0.5 0.5 1"/>
      </material>
    </visual>
    <collision>
      <origin rpy="0.0 0 0" xyz="0 0.2 0"/>
      <geometry>
        <box size="0.1 0.4 0.1"/>
      </geometry>
    </collision>
    <collision2>
      <origin rpy="0.0 0 0" xyz="0 0.2 0"/>
      <geometry>
        <capsule radius="0.1" length = "0.4"/>
      </geometry>
    </collision2>
  </link>
  <joint name="4_joint" type="revolute">
    <origin rpy="0 0 0" xyz="0 0.4 0"/>
    <axis xyz="0 0 1"/>
    <limit effort="100" lower="-2.792444444" upper="2.792444444" velocity="100"/>
    <parent link="link4"/>
    <child link="link5"/>
  </joint>
  <link name="link5">
    <visual>
      <origin rpy="0.0 0 0" xyz="0 0.05 0"/>
      <geometry>
        <box size="0.1 0.1 0.1"/>
      </geometry>
      <material name="link">
        <color rgba="0.5 0.5 0.5 1"/>
      </material>
    </visual>
    <collision>
      <origin rpy="0.0 0 0" xyz="0 0.05 0"/>
      <geometry>
        <box size="0.1 0.1 0.1"/>
      </geometry>
    </collision>
    <collision2>
      <origin rpy="0.0 0 0" xyz="0 0.05 0"/>
      <geometry>
        <sphere radius="0.1"/>
      </geometry>
    </collision2>
  </link>
  <joint name="effector_joint" type="fixed">
    <origin rpy="0 0 0" xyz="0 0.15 0"/>
    <parent link="link5"/>
    <child link="effector"/>
  </joint>
  <link name="effector">
    <visual>
      <origin rpy="0.0 0 0" xyz="0 0 0"/>
      <geometry>
        <box size="0.1 0.1 0.1"/>
      </geometry>
      <material name="effector">
        <color rgba="0.1 0.1 0.9 1"/>
      </material>
    </visual>
    <collision>
      <origin rpy="0.0 0 0" xyz="0 0 0"/>
      <geometry>
        <box size="0.1 0.1 0.1"/>
      </geometry>
    </collision>
    <collision2>
      <origin rpy="0.0 0 0" xyz="0 0 0"/>
      <geometry>
        <sphere radius="0.1"/>
      </geometry>
    </collision2>
  </link>
</robot>
